Workbook

Sheet Properties
B2: PROJECT PROPERTIES
B4: Company: | C4: PPDK IIUM Gombak
B6: Project: | C6: Community-Based Rehabilitation Management System
B8: Quality Analyst: | C8: [Tester Name]

Sheet Test Cases
G2: TEST RESULTS
G4: Status | I4: Exec Tm | J4: Count
G5: To Do | H5: T | I5: =SUMIF($D$18:$D$314,$H5,$C$18:$C$314)/60 -> 0 | J5: =COUNTIF($D$18:$D$314,$H5) -> 72
G6: Blocked | H6: B | I6: =SUMIF($D$18:$D$314,$H6,$C$18:$C$314)/60 -> 0 | J6: =COUNTIF($D$18:$D$314,$H6) -> 0
G7: Fail | H7: F | I7: =SUMIF($D$18:$D$314,$H7,$C$18:$C$314)/60 -> 0 | J7: =COUNTIF($D$18:$D$314,$H7) -> 0
G8: Qualified Pass | H8: Q | I8: =SUMIF($D$18:$D$314,$H8,$C$18:$C$314)/60 -> 0 | J8: =COUNTIF($D$18:$D$314,$H8) -> 0
G9: Pass | H9: P | I9: =SUMIF($D$18:$D$314,$H9,$C$18:$C$314)/60 -> 0 | J9: =COUNTIF($D$18:$D$314,$H9) -> 0
G10: Information | H10: i | I10: =SUMIF($D$18:$D$314,$H10,$C$18:$C$314)/60 -> 0
I11: =SUM(I5:I10) -> 0 | J11: =SUM(J5:J10) -> 72
G13: =IF(COUNTIF(G14:G16, "") <> 3, "VALIDATION ERROR!", "") -> VALIDATION ERROR!
G14: =IF($C$314<>$E$314,"REJ-01: " & $C$314&" [Exec Tm] rows <> " & $E$314 & " [Test Steps] rows", "") -> REJ-01: 295 [Exec Tm] rows <> 222 [Test Steps] rows
G15: =IF($D$314<>$E$314,"REJ-02: " & $D$314&" [Status] rows <> " & $E$314 & " [Test Steps] rows", "") -> REJ-02: 221 [Status] rows <> 222 [Test Steps] rows
A17: ▪ | B17: TEST CASES | F17: ▪
B18: # | C18: Exec Tm | D18: Stat | E18: Test Steps (Use Alt+Enter to add blank lines in same cell)
B19: {=IF(AND(C19<>"",E19<>"")=TRUE, CELL("row",B19)-18,"")} | D19: T
D20: T | E20: PUBLIC ACCESS MODULE HOME001 - Welcome/Landing Page Load and Verification 1. Navigate to Application Homepage - Open browser (Chrome, Firefox, Safari, Edge) - Navigate to the CREAMS application URL - Clear browser cache before testing 2. Test Initial Page Load: - Verify page loads within 3 seconds - Check that no console errors appear - Verify all images load correctly - Check that CSS styling is applied properly - Verify responsive design on different screen sizes 3. Test Welcome Page Content: - Verify page title displays correctly - Check that organization logo/branding appears - Verify welcome message is clear and visible - Check that navigation menu is accessible - Verify footer information displays 4. Test Navigation Elements: - Verify "About Us" link is clickable - Check "Contact Us" link functionality - Verify "Login" button is prominent and accessible - Test all menu items for proper linking 5. Test Performance: - Measure page load time (should be <3 seconds) - Check loading indicators work properly - Verify smooth scrolling behavior - Test page on slow network connection 6. Test Accessibility: - Verify keyboard navigation works - Check screen reader compatibility - Verify color contrast meets standards - Test with browser zoom at 150% and 200%
B21: {=IF(AND(C21<>"",E21<>"")=TRUE, CELL("row",B21)-18,"")} | D21: T | E21: HOME002 - Public Information Display 1. Navigate to About Us Section - Click on "About Us" from navigation menu - Verify URL changes appropriately 2. Test Information Display: - Verify organization mission statement displays - Check that program descriptions are complete - Verify contact information is accurate - Check that all text is readable and properly formatted 3. Test Content Accessibility: - Verify all sections load without authentication - Check that public content is not restricted - Verify no sensitive data is exposed - Test content on mobile devices 4. Test Navigation: - Verify ability to navigate between sections - Check breadcrumb navigation if applicable - Test "Back to Home" functionality
B22: {=IF(AND(C22<>"",E22<>"")=TRUE, CELL("row",B22)-18,"")} | D22: T | E22: CONTACT001 - Contact Us Form Submission 1. Navigate to Contact Us Page (/contact) - Click "Contact Us" from navigation - Verify form loads completely 2. Test Form Display: - Verify all required fields are marked with asterisk (*) - Check field labels are clear and visible - Verify form instructions are provided - Check that CAPTCHA/anti-spam protection displays 3. Test Form Validation: - Submit empty form - verify error messages appear - Enter invalid email format - check validation message - Enter phone number with letters - verify validation - Leave required fields empty - check error handling - Enter special characters in name field - verify validation 4. Test Valid Form Submission: - Fill in Name: "Test User" - Enter valid Email: "testuser@example.com" - Enter Phone: "+60123456789" - Enter Subject: "General Inquiry" - Enter Message: "This is a test inquiry message" - Submit form 5. Test Submission Confirmation: - Verify success message displays - Check that confirmation email is sent (if applicable) - Verify form clears after successful submission - Check that submission is saved in system 6. Test Error Handling: - Test submission with network disconnected - Verify appropriate error message displays - Check that form data is preserved after error - Test retry functionality
B23: {=IF(AND(C23<>"",E23<>"")=TRUE, CELL("row",B23)-18,"")} | D23: T | E23: AUTHENTICATION MODULE AUTH001 - Standard Login Functionality 1. Navigate to Login Page (/login) - Click "Login" button from homepage - Verify login form displays correctly - Check page loads within 2 seconds 2. Test Login Form Display: - Verify username/email field is visible - Check password field masks characters - Verify "Show Password" toggle works - Check "Remember Me" checkbox (if applicable) - Verify "Forgot Password?" link is present 3. Test Login Validation: - Submit empty form - verify validation messages - Enter invalid email format - check error message - Enter whitespace in fields - verify trimming/validation - Test SQL injection attempts - verify protection - Test XSS attempts - verify sanitization 4. Test Invalid Login Attempts: - Enter valid username, wrong password - verify error - Enter invalid username - verify generic error message - Test account lockout after 5 failed attempts - Verify error messages don't reveal user existence 5. Test Valid Login - Administrator: - Username: Valid admin username - Password: Correct password - Click "Login" button - Verify redirect to admin dashboard - Check session is created - Verify user role is set correctly 6. Test Valid Login - Teacher: - Enter valid teacher credentials - Verify redirect to teacher dashboard - Check appropriate permissions are applied 7. Test Valid Login - Supervisor: - Enter valid supervisor credentials - Verify redirect to supervisor dashboard - Check role-specific features are accessible 8. Test Session Management: - Verify session timeout after 30 minutes inactivity - Test "Remember Me" functionality (7-day session) - Verify single session enforcement (optional) - Test concurrent login handling 9. Test Security Features: - Verify CSRF token is present - Check that password is sent over HTTPS - Verify session cookie is secure and HttpOnly - Test brute force protection
B24: {=IF(AND(C24<>"",E24<>"")=TRUE, CELL("row",B24)-18,"")} | D24: T | E24: AUTH002 - Enhanced Login with Multi-Factor Options 1. Navigate to Enhanced Login (/enhanced-login) - Access the enhanced login page - Verify modern UI displays correctly 2. Test Enhanced Features: - Verify password strength indicator - Test "Show/Hide Password" toggle - Check biometric login option (if available) - Verify QR code login (if implemented) 3. Test Two-Factor Authentication: - Login with valid credentials - Verify 2FA prompt appears - Enter valid OTP code - Check successful authentication - Test invalid OTP handling - Verify OTP expiration (5 minutes) 4. Test Remember Device Feature: - Enable "Remember this device" - Logout and login again - Verify 2FA is skipped on remembered device - Test device trust duration (30 days)
B25: {=IF(AND(C25<>"",E25<>"")=TRUE, CELL("row",B25)-18,"")} | D25: T | E25: AUTH003 - User Registration Process 1. Navigate to Registration Page (/staffs/register) - Access staff registration page - Verify only admin can access (role check) 2. Test Registration Form Display: - Verify all required fields are marked - Check field groupings are logical - Verify helper text is provided - Check password requirements are displayed 3. Test Form Validation: - Test IIUM ID format validation (uppercase, correct pattern) - Verify email uniqueness check - Test password strength requirements: * Minimum 8 characters * At least one uppercase letter * At least one lowercase letter * At least one number * At least one special character - Verify password confirmation matching 4. Test Role Selection: - Verify Administrator option available - Check Teacher option available - Verify Supervisor option available - Test radio button functionality 5. Test Centre Assignment: - Verify centre dropdown populates - Check multiple centres available - Test required field validation 6. Test Valid Registration - Administrator: - IIUM ID: "ADMIN123" - Name: "Test Administrator" - Email: "admin.test@example.com" - Password: "SecurePass123!" - Confirm Password: "SecurePass123!" - Role: Administrator - Centre: Select valid centre - Submit form 7. Test Registration Success: - Verify success message displays - Check redirect to user list - Verify new user appears in system - Check welcome email sent (if applicable) 8. Test Duplicate Prevention: - Attempt to register with existing IIUM ID - Verify error message displays - Test duplicate email handling - Check form preserves data after error 9. Test Role-Based Registration: - Register Teacher account - verify limited permissions - Register Supervisor account - verify supervisor capabilities - Test that registered users can login immediately
B26: {=IF(AND(C26<>"",E26<>"")=TRUE, CELL("row",B26)-18,"")} | D26: T | E26: AUTH004 - Password Reset Flow 1. Navigate to Forgot Password Page (/forgot-password) - Click "Forgot Password?" link from login - Verify reset form displays 2. Test Password Reset Request: - Enter registered email address - Submit reset request - Verify success message displays - Check that reset email is sent - Verify reset token is generated 3. Test Reset Email: - Check email received in inbox - Verify reset link is present - Check token expiration notice (24 hours) - Test link formatting is correct 4. Test Reset Link Access: - Click reset link from email - Verify redirect to reset password page - Check token is valid - Verify form displays with token pre-filled 5. Test New Password Setting: - Enter new password: "NewSecurePass456!" - Confirm new password: "NewSecurePass456!" - Verify password strength indicator - Submit new password 6. Test Reset Success: - Verify success confirmation message - Check redirect to login page - Test login with new password succeeds - Verify old password no longer works 7. Test Security Validations: - Test expired token (after 24 hours) - Test already-used token - Verify invalid token returns error - Test rate limiting on reset requests
B27: {=IF(AND(C27<>"",E27<>"")=TRUE, CELL("row",B27)-18,"")} | D27: T | E27: AUTH005 - Logout Functionality 1. Test Standard Logout: - Click "Logout" button from any page - Verify confirmation prompt (optional) - Check session is destroyed - Verify redirect to homepage/login 2. Test Post-Logout Security: - Attempt to access protected pages after logout - Verify redirect to login page - Check browser back button doesn't restore session - Verify session cookie is cleared 3. Test Session Timeout Logout: - Login and remain inactive for 30 minutes - Attempt to perform an action - Verify automatic logout occurs - Check timeout warning message (if implemented)
B28: {=IF(AND(C28<>"",E28<>"")=TRUE, CELL("row",B28)-18,"")} | D28: T | E28: DASHBOARD MODULE DASH001 - Admin Dashboard Display 1. Login as Administrator - Use valid admin credentials - Verify successful authentication 2. Navigate to Dashboard (/dashboard) - Check automatic redirect after login - Verify page loads within 2 seconds 3. Test Dashboard Widgets: - Verify total users count displays - Check total trainees count is accurate - Verify active activities count - Check attendance summary widget - Verify recent registrations list - Check system notifications panel 4. Test Statistics Display: - Verify charts render correctly (bar, pie, line charts) - Check data accuracy by comparing with database - Test chart interactions (hover, click) - Verify date range filters work 5. Test Quick Actions Panel: - Verify "Add New Trainee" button present - Check "Create Activity" shortcut works - Verify "Generate Report" link functions - Test "System Settings" access 6. Test Recent Activity Feed: - Verify last 10 activities display - Check timestamps are correct - Verify activity links are clickable - Test real-time updates (if implemented) 7. Test Navigation Sidebar: - Verify all menu items are accessible - Check active menu highlighting - Test menu collapse/expand functionality - Verify submenu navigation 8. Test Role-Based Content: - Verify admin-only sections are visible - Check that sensitive data displays appropriately - Test that all management options are available
B29: {=IF(AND(C29<>"",E29<>"")=TRUE, CELL("row",B29)-18,"")} | D29: T | E29: DASH002 - Teacher Dashboard Display 1. Login as Teacher - Use valid teacher credentials - Navigate to dashboard 2. Test Teacher-Specific Widgets: - Verify "My Classes" widget displays assigned activities - Check "Today's Schedule" shows current day sessions - Verify "My Trainees" count displays - Check "Pending Attendance" alerts 3. Test Limited Access: - Verify system administration options are hidden - Check that teacher can only see own classes - Verify financial data is not accessible - Test that user management is restricted 4. Test Class Management Shortcuts: - Verify "Mark Attendance" quick access - Check "View My Schedule" link - Test "Message Trainees" functionality
B30: {=IF(AND(C30<>"",E30<>"")=TRUE, CELL("row",B30)-18,"")} | D30: T | E30: DASH003 - Supervisor Dashboard Display 1. Login as Supervisor - Use valid supervisor credentials - Navigate to dashboard 2. Test Supervisor-Specific Features: - Verify oversight of assigned teachers - Check team performance metrics - Verify ability to view teacher schedules - Test access to teacher management options 3. Test Reporting Access: - Verify access to team reports - Check performance analytics - Test export functionality for supervisor reports
B31: {=IF(AND(C31<>"",E31<>"")=TRUE, CELL("row",B31)-18,"")} | D31: T | E31: DASH004 - Dashboard Responsiveness 1. Test on Desktop (1920x1080): - Verify full layout displays correctly - Check all widgets are properly sized - Test sidebar and content area proportions 2. Test on Tablet (768x1024): - Verify responsive layout adapts - Check sidebar collapses to hamburger menu - Test widget stacking behavior 3. Test on Mobile (375x667): - Verify mobile-optimized layout - Check touch-friendly controls - Test scrolling behavior - Verify no horizontal scrolling
B32: {=IF(AND(C32<>"",E32<>"")=TRUE, CELL("row",B32)-18,"")} | D32: T | E32: PROFILE MODULE PROF001 - View User Profile 1. Navigate to Profile Page (/profile) - Click on user avatar/name in navigation - Select "My Profile" option 2. Test Profile Display: - Verify IIUM ID displays (read-only) - Check full name is correct - Verify email address shows - Check role displays correctly - Verify centre assignment shows - Check profile image displays (or default avatar) 3. Test Profile Information Layout: - Verify sections are clearly labeled - Check data is properly formatted - Test responsive layout on different screens
... B92: {=IF(AND(C92<>"",E92<>"")=TRUE, CELL("row",B92)-18,"")} | D92: i | E92: NOTES FOR TESTERS **Prerequisites:** - Test environment with clean database - Sample data populated (users, centres, categories) - Multiple user accounts with different roles - Test email/SMS accounts for notifications - Document management system accessible - Backup of production data (if testing on production) **Best Practices:** - Clear browser cache between major test sections - Use different browsers (Chrome, Firefox, Safari, Edge) - Test on multiple devices (desktop, tablet, mobile) - Document any bugs with screenshots - Note performance issues with timestamps - Keep track of test data used - Reset test environment after each phase **Critical Areas Requiring Extra Attention:** - Authentication and session management - Role-based access control - Data validation across all forms - Notification delivery - Report accuracy - Data consistency across modules - Performance with large datasets
B93: {=IF(AND(C93<>"",E93<>"")=TRUE, CELL("row",B93)-18,"")}
B94: {=IF(AND(C94<>"",E94<>"")=TRUE, CELL("row",B94)-18,"")}
B95: {=IF(AND(C95<>"",E95<>"")=TRUE, CELL("row",B95)-18,"")}
B96: {=IF(AND(C96<>"",E96<>"")=TRUE, CELL("row",B96)-18,"")}
B97: {=IF(AND(C97<>"",E97<>"")=TRUE, CELL("row",B97)-18,"")}
B98: {=IF(AND(C98<>"",E98<>"")=TRUE, CELL("row",B98)-18,"")}
B99: {=IF(AND(C99<>"",E99<>"")=TRUE, CELL("row",B99)-18,"")}
B100: {=IF(AND(C100<>"",E100<>"")=TRUE, CELL("row",B100)-18,"")}
B101: {=IF(AND(C101<>"",E101<>"")=TRUE, CELL("row",B101)-18,"")}
B102: {=IF(AND(C102<>"",E102<>"")=TRUE, CELL("row",B102)-18,"")}
B103: {=IF(AND(C103<>"",E103<>"")=TRUE, CELL("row",B103)-18,"")}
...

Sheet Test Run Log
B1: TEST RESULTS RUN LOG
B3: Run # | C3: Test Run Description | D3: Date | E3: Exec Time (hr) | F3: Test Cases | L3: Defects
F4: ToDo | G4: Block | H4: Fail | I4: Qpass | J4: Pass | K4: Total | L4: Open, Stop | M4: Open, Allow | N4: Defer | O4: Closed | P4: Total
B5: R1 | K5: =IF(SUM(F5:J5)=0, "", SUM(F5:J5)) | P5: =IF(SUM(L5:O5)=0, "", SUM(L5:O5))
B6: R2 | K6: =IF(SUM(F6:J6)=0, "", SUM(F6:J6)) | P6: =IF(SUM(L6:O6)=0, "", SUM(L6:O6))
B7: R3 | K7: =IF(SUM(F7:J7)=0, "", SUM(F7:J7)) | P7: =IF(SUM(L7:O7)=0, "", SUM(L7:O7))
B8: R4 | K8: =IF(SUM(F8:J8)=0, "", SUM(F8:J8)) | P8: =IF(SUM(L8:O8)=0, "", SUM(L8:O8))
B9: R5 | K9: =IF(SUM(F9:J9)=0, "", SUM(F9:J9)) | P9: =IF(SUM(L9:O9)=0, "", SUM(L9:O9))
B10: R6 | K10: =IF(SUM(F10:J10)=0, "", SUM(F10:J10)) | P10: =IF(SUM(L10:O10)=0, "", SUM(L10:O10))
B11: R7 | K11: =IF(SUM(F11:J11)=0, "", SUM(F11:J11)) | P11: =IF(SUM(L11:O11)=0, "", SUM(L11:O11))
B12: R8 | K12: =IF(SUM(F12:J12)=0, "", SUM(F12:J12)) | P12: =IF(SUM(L12:O12)=0, "", SUM(L12:O12))
B13: R9 | K13: =IF(SUM(F13:J13)=0, "", SUM(F13:J13)) | P13: =IF(SUM(L13:O13)=0, "", SUM(L13:O13))
B14: R10 | K14: =IF(SUM(F14:J14)=0, "", SUM(F14:J14)) | P14: =IF(SUM(L14:O14)=0, "", SUM(L14:O14))
B15: R11 | K15: =IF(SUM(F15:J15)=0, "", SUM(F15:J15)) | P15: =IF(SUM(L15:O15)=0, "", SUM(L15:O15))
B16: R12 | K16: =IF(SUM(F16:J16)=0, "", SUM(F16:J16)) | P16: =IF(SUM(L16:O16)=0, "", SUM(L16:O16))

Sheet Report
B1: TEST RESULTS REPORT
C2: Company: | D2: =IF(Properties!$C$4=0, "", Properties!$C$4) -> PPDK IIUM Gombak | M2: Test Run: | N2: {=INDEX('Test Run Log'!$B$14:$B$16,MATCH(MAX(COUNTIF('Test Run Log'!$B$14:$B$16, "<" & 'Test Run Log'!$B$14:$B$16)), COUNTIF('Test Run Log'!$B$14:$B$16, "<"&'Test Run Log'!$B$14:$B$16),0))} -> R12
C3: Project: | D3: =IF(Properties!$C$6=0, "", Properties!$C$6) -> Community-Based Rehabilitation Management System | M3: Tested By: | N3: =IF(Properties!$C$8=0, "", Properties!$C$8) -> [Tester Name]
M4: Total Test Cases: | N4: =SUM(C14:G14) -> 0
M5: Total Defects: | N5: =SUM(K14:M14) -> 0
B7: ="TEST CASE COUNTS - SNAPSHOT @ " & $N$2 -> TEST CASE COUNTS - SNAPSHOT @ R12 | J7: ="DEFECTS - SNAPSHOT @ " & $N$2 -> DEFECTS - SNAPSHOT @ R12
C13: ToDo | D13: Block | E13: Fail | F13: Qpass | G13: Pass | K13: Open | L13: Defer | M13: Close
B14: =$N$2 -> R12 | C14: =VLOOKUP($N$2,'Test Run Log'!$B$14:$K$16,5) -> 0 | D14: =VLOOKUP($N$2,'Test Run Log'!$B$14:$K$16,6) -> 0 | E14: =VLOOKUP($N$2,'Test Run Log'!$B$14:$K$16,7) -> 0 | F14: =VLOOKUP($N$2,'Test Run Log'!$B$14:$K$16,8) -> 0 | G14: =VLOOKUP($N$2,'Test Run Log'!$B$14:$K$16,9) -> 0 | J14: =$N$2 -> R12 | K14: =VLOOKUP($N$2,'Test Run Log'!$B$14:$O$16,11)+VLOOKUP($N$2,'Test Run Log'!$B$14:$O$16,12) -> 0 | L14: =VLOOKUP($N$2,'Test Run Log'!$B$14:$O$16,13) -> 0 | M14: =VLOOKUP($N$2,'Test Run Log'!$B$14:$O$16,14) -> 0
B17: ="TEST CASE COUNTS - TREND" -> TEST CASE COUNTS - TREND | J17: ="DEFECTS - TREND" -> DEFECTS - TREND
B29: ="TEST CASE EXEC TIME - TREND" -> TEST CASE EXEC TIME - TREND | J29: ="DEFECTS - RELEASABILITY" -> DEFECTS - RELEASABILITY
B42: DEFECTS - CURRENTLY OPENED
B43: Pr | C43: Description
B50: DEFECTS - CLOSED SINCE LAST REPORT
B51: Pr | C51: Description
B58: DEFECTS - CLOSED SINCE PROJECT STARTED
B59: Pr | C59: Description
